<mujoco model="panda tactile grasping">
  <compiler angle="radian" />
  
  <option timestep="0.002" gravity="0 0 -9.81" />
  
  <default>
    <joint armature="0.1" damping="1" limited="true" />
    <geom contype="1" conaffinity="1" friction="1 0.5 0.5" />
    <position ctrllimited="true" />
  </default>
  
  <asset>
    <texture type="skybox" builtin="gradient" rgb1="0.3 0.5 0.7" rgb2="0 0 0" width="512" height="3072"/>
    <texture type="2d" name="groundplane" builtin="checker" mark="edge" rgb1="0.2 0.3 0.4" rgb2="0.1 0.2 0.3" 
             markrgb="0.8 0.8 0.8" width="300" height="300"/>
    <material name="groundplane" texture="groundplane" texuniform="true" texrepeat="5 5" reflectance="0.2"/>
    <material name="table" rgba="0.8 0.7 0.6 1" />
    <material name="gripper" rgba="0.9 0.9 0.9 1" />
    <material name="cube" rgba="0.2 0.8 0.2 1" />
  </asset>
  
  <worldbody>
    <!-- Ground -->
    <geom name="floor" size="0 0 0.05" type="plane" material="groundplane"/>
    
    <!-- Table -->
    <body name="table" pos="0.5 0 0.4">
      <geom name="table_top" type="box" size="0.4 0.4 0.02" material="table" />
    </body>
    
    <!-- Simple 2-DOF arm for easier control -->
    <body name="arm_base" pos="0.5 0 0.82">
      <!-- Vertical link -->
      <geom name="link0" type="cylinder" size="0.05 0.2" rgba="0.7 0.7 0.7 1" />
      <joint name="arm_lift" type="slide" axis="0 0 1" range="-0.3 0.3" />
      
      <body name="arm_link" pos="0 0 0.2">
        <!-- Horizontal link -->
        <geom name="link1" type="box" size="0.3 0.04 0.04" pos="0.3 0 0" rgba="0.7 0.7 0.7 1" />
        <joint name="arm_extend" type="slide" axis="1 0 0" range="-0.2 0.2" />
        
        <!-- Gripper base -->
        <body name="gripper_base" pos="0.6 0 0">
          <geom name="gripper_mount" type="cylinder" size="0.03 0.05" rgba="0.8 0.8 0.8 1" />
          <joint name="gripper_rotate" type="hinge" axis="0 0 1" range="-1.57 1.57" />
          
          <!-- Left finger -->
          <body name="left_finger" pos="0 0.02 -0.05">
            <geom name="left_finger_geom" type="box" size="0.01 0.01 0.04" material="gripper" />
            <joint name="left_finger_joint" type="slide" axis="0 1 0" range="0 0.04" />
            <!-- Tactile pad with proper collision -->
            <geom name="left_finger_pad" type="box" size="0.008 0.008 0.03" pos="0 -0.01 0" 
                  rgba="0.8 0.2 0.2 1" contype="1" conaffinity="1" />
          </body>
          
          <!-- Right finger -->
          <body name="right_finger" pos="0 -0.02 -0.05">
            <geom name="right_finger_geom" type="box" size="0.01 0.01 0.04" material="gripper" />
            <joint name="right_finger_joint" type="slide" axis="0 -1 0" range="0 0.04" />
            <!-- Tactile pad with proper collision -->
            <geom name="right_finger_pad" type="box" size="0.008 0.008 0.03" pos="0 0.01 0" 
                  rgba="0.8 0.2 0.2 1" contype="1" conaffinity="1" />
          </body>
          
          <!-- End effector site -->
          <site name="gripper" pos="0 0 -0.1" size="0.01" />
        </body>
      </body>
    </body>
    
    <!-- Cube to grasp -->
    <body name="cube" pos="0.5 0 0.44">
      <freejoint />
      <geom name="cube" type="box" size="0.025 0.025 0.025" material="cube" 
            contype="1" conaffinity="1" friction="1 0.5 0.5" />
    </body>
  </worldbody>
  
  <actuator>
    <!-- Arm actuators -->
    <position name="arm_lift_act" joint="arm_lift" kp="500" ctrlrange="-0.3 0.3" />
    <position name="arm_extend_act" joint="arm_extend" kp="500" ctrlrange="-0.2 0.2" />
    <position name="gripper_rotate_act" joint="gripper_rotate" kp="100" ctrlrange="-1.57 1.57" />
    
    <!-- Gripper actuators -->
    <position name="left_finger_act" joint="left_finger_joint" kp="100" ctrlrange="0 0.04" />
    <position name="right_finger_act" joint="right_finger_joint" kp="100" ctrlrange="0 0.04" />
  </actuator>
  
  <equality>
    <!-- Couple the two fingers -->
    <joint joint1="left_finger_joint" joint2="right_finger_joint" polycoef="0 1 0 0 0" />
  </equality>
</mujoco>