<mujoco model="panda">
  <compiler angle="radian" meshdir="assets" autolimits="true"/>
  <option impratio="20" cone="elliptic" density="1.2" viscosity="0.00002" timestep="0.002" />
  <size nconmax="5000" njmax="5000" />
  
  <option integrator="implicitfast"/>

  <default>
    <default class="panda">
      <material specular="0.5" shininess="0.25"/>
      <joint armature="0.1" damping="1" axis="0 0 1" range="-2.8973 2.8973"/>
      <default class="finger">
        <joint axis="0 1 0" type="slide" range="0 0.04"/>
      </default>
      <default class="visual">
        <geom type="mesh" contype="0" conaffinity="0" group="2"/>
      </default>
      <default class="collision">
        <geom type="mesh" group="3"/>
      </default>
    </default>
  </default>

  <asset>
    <material class="panda" name="white" rgba="1 1 1 1"/>
    <material class="panda" name="off_white" rgba="0.901961 0.921569 0.929412 1"/>
    <material class="panda" name="black" rgba="0.25 0.25 0.25 1"/>
    <material class="panda" name="green" rgba="0 1 0 1"/>
    <material class="panda" name="light_blue" rgba="0.039216 0.541176 0.780392 1"/>

    <!-- Add materials for the table -->
    <material name="table_ceramic" rgba="0.8 0.8 0.8 1" shininess="0.0" specular="0.2"/>
    <material name="table_legs_metal" rgba="0.4 0.4 0.4 1" shininess="0.8" reflectance="0.8"/>

    <!-- Sensor pad material -->
    <material name="sensor_pad_material" rgba="0.3 0.3 0.8 0.5" shininess="0.0" specular="0.0"/>
    
    <!-- Cube materials to match original environment -->
    <material name="cubeA_redwood_mat" rgba="1 0 0 1" specular="0.4" shininess="0.1"/>
    <material name="cubeB_greenwood_mat" rgba="0 1 0 1" specular="0.4" shininess="0.1"/>

    <!-- Collision meshes -->
    <mesh name="link0_c" file="link0.stl"/>
    <mesh name="link1_c" file="link1.stl"/>
    <mesh name="link2_c" file="link2.stl"/>
    <mesh name="link3_c" file="link3.stl"/>
    <mesh name="link4_c" file="link4.stl"/>
    <mesh name="link5_c0" file="link5_collision_0.obj"/>
    <mesh name="link5_c1" file="link5_collision_1.obj"/>
    <mesh name="link5_c2" file="link5_collision_2.obj"/>
    <mesh name="link6_c" file="link6.stl"/>
    <mesh name="link7_c" file="link7.stl"/>
    <mesh name="hand_c" file="hand.stl"/>

    <!-- Visual meshes -->
    <mesh file="link0_0.obj"/>
    <mesh file="link0_1.obj"/>
    <mesh file="link0_2.obj"/>
    <mesh file="link0_3.obj"/>
    <mesh file="link0_4.obj"/>
    <mesh file="link0_5.obj"/>
    <mesh file="link0_7.obj"/>
    <mesh file="link0_8.obj"/>
    <mesh file="link0_9.obj"/>
    <mesh file="link0_10.obj"/>
    <mesh file="link0_11.obj"/>
    <mesh file="link1.obj"/>
    <mesh file="link2.obj"/>
    <mesh file="link3_0.obj"/>
    <mesh file="link3_1.obj"/>
    <mesh file="link3_2.obj"/>
    <mesh file="link3_3.obj"/>
    <mesh file="link4_0.obj"/>
    <mesh file="link4_1.obj"/>
    <mesh file="link4_2.obj"/>
    <mesh file="link4_3.obj"/>
    <mesh file="link5_0.obj"/>
    <mesh file="link5_1.obj"/>
    <mesh file="link5_2.obj"/>
    <mesh file="link6_0.obj"/>
    <mesh file="link6_1.obj"/>
    <mesh file="link6_2.obj"/>
    <mesh file="link6_3.obj"/>
    <mesh file="link6_4.obj"/>
    <mesh file="link6_5.obj"/>
    <mesh file="link6_6.obj"/>
    <mesh file="link6_7.obj"/>
    <mesh file="link6_8.obj"/>
    <mesh file="link6_9.obj"/>
    <mesh file="link6_10.obj"/>
    <mesh file="link6_11.obj"/>
    <mesh file="link6_12.obj"/>
    <mesh file="link6_13.obj"/>
    <mesh file="link6_14.obj"/>
    <mesh file="link6_15.obj"/>
    <mesh file="link6_16.obj"/>
    <mesh file="link7_0.obj"/>
    <mesh file="link7_1.obj"/>
    <mesh file="link7_2.obj"/>
    <mesh file="link7_3.obj"/>
    <mesh file="link7_4.obj"/>
    <mesh file="link7_5.obj"/>
    <mesh file="link7_6.obj"/>
    <mesh file="link7_7.obj"/>
    <mesh file="hand_0.obj"/>
    <mesh file="hand_1.obj"/>
    <mesh file="hand_2.obj"/>
    <mesh file="hand_3.obj"/>
    <mesh file="hand_4.obj"/>
    <mesh file="finger_0.obj"/>
    <mesh file="finger_1.obj"/>
  </asset>

  <worldbody>
    <light name="top" pos="0 0 2" mode="trackcom"/>
    
    <!-- Modified table body - removed static attribute and adjusted height -->
    <body name="table" pos="0.0 0.0 0.775">
      <geom pos="0 0 0" size="0.4 0.4 0.025" type="box" group="3" name="table_collision" friction="1.0 0.005 0.0001" rgba="0.5 0.5 0 1" />
      <geom pos="0 0 0" size="0.4 0.4 0.025" type="box" conaffinity="0" contype="0" group="2" name="table_visual" material="table_ceramic" />
      
      <!-- Adjusted table legs to match original -->
      <geom pos="0.30 0.30 -0.3875" size="0.025 0.3875" type="cylinder" conaffinity="0" contype="0" group="2" name="table_leg1_visual" material="table_legs_metal" />
      <geom pos="-0.30 0.30 -0.3875" size="0.025 0.3875" type="cylinder" conaffinity="0" contype="0" group="2" name="table_leg2_visual" material="table_legs_metal" />
      <geom pos="-0.30 -0.30 -0.3875" size="0.025 0.3875" type="cylinder" conaffinity="0" contype="0" group="2" name="table_leg3_visual" material="table_legs_metal" />
      <geom pos="0.30 -0.30 -0.3875" size="0.025 0.3875" type="cylinder" conaffinity="0" contype="0" group="2" name="table_leg4_visual" material="table_legs_metal" />
      
      <!-- Added table_top site from original -->
      <site pos="0.0 0.0 0.025" name="table_top" size="0.001 0.001 0.001" rgba="0 0 0 0" />
    </body>
    
    <!-- Updated cubes to match original environment's structure -->
    <!-- cubeA: 2cm × 2cm × 2cm -->
    <body name="cubeA_main" pos="0.0 0.0 0.825">
      <joint type="free" name="cubeA_joint0" />
      <geom type="box" name="cubeA_g0" size="0.02 0.02 0.02" condim="3"
       friction="1 0.005 0.0001" solref="0.02 1.0" solimp="0.9 0.95 0.001" rgba="0.5 0 0 1" density="1000" group="3" />
      <geom type="box" name="cubeA_g0_vis" size="0.02 0.02 0.02" conaffinity="0" contype="0" mass="1e-8" material="cubeA_redwood_mat" group="2" />
      <site type="sphere" group="0" pos="0 0 0" size="0.002 0.002 0.002" rgba="1 0 0 1" name="cubeA_default_site" />
    </body>
    
    <!-- cubeB: 2.5cm × 2.5cm × 2.5cm -->
    <body name="cubeB_main" pos="0.0 0.1 0.825">
      <joint type="free" name="cubeB_joint0" />
      <geom type="box" name="cubeB_g0" size="0.025 0.025 0.025" condim="3"
       friction="1 0.005 0.0001" solref="0.02 1.0" solimp="0.9 0.95 0.001" rgba="0.5 0 0 1" density="1000" group="3" />
      <geom type="box" name="cubeB_g0_vis" size="0.025 0.025 0.025" conaffinity="0" contype="0" mass="1e-8" material="cubeB_greenwood_mat" group="2" />
      <site type="sphere" group="0" pos="0 0 0" size="0.002 0.002 0.002" rgba="1 0 0 1" name="cubeB_default_site" />
    </body>
    
    <body name="link0" childclass="panda">
      <inertial mass="0.629769" pos="-0.041018 -0.00014 0.049974"
        fullinertia="0.00315 0.00388 0.004285 8.2904e-7 0.00015 8.2299e-6"/>
      <geom mesh="link0_0" material="off_white" class="visual"/>
      <geom mesh="link0_1" material="black" class="visual"/>
      <geom mesh="link0_2" material="off_white" class="visual"/>
      <geom mesh="link0_3" material="black" class="visual"/>
      <geom mesh="link0_4" material="off_white" class="visual"/>
      <geom mesh="link0_5" material="black" class="visual"/>
      <geom mesh="link0_7" material="white" class="visual"/>
      <geom mesh="link0_8" material="white" class="visual"/>
      <geom mesh="link0_9" material="black" class="visual"/>
      <geom mesh="link0_10" material="off_white" class="visual"/>
      <geom mesh="link0_11" material="white" class="visual"/>
      <geom mesh="link0_c" class="collision"/>
      <body name="link1" pos="0 0 0.333">
        <inertial mass="4.970684" pos="0.003875 0.002081 -0.04762"
          fullinertia="0.70337 0.70661 0.0091170 -0.00013900 0.0067720 0.019169"/>
        <joint name="robot0_joint1"/>
        <geom material="white" mesh="link1" class="visual"/>
        <geom mesh="link1_c" class="collision"/>
        <body name="link2" quat="1 -1 0 0">
          <inertial mass="0.646926" pos="-0.003141 -0.02872 0.003495"
            fullinertia="0.0079620 2.8110e-2 2.5995e-2 -3.925e-3 1.0254e-2 7.04e-4"/>
          <joint name="robot0_joint2" range="-1.7628 1.7628"/>
          <geom material="white" mesh="link2" class="visual"/>
          <geom mesh="link2_c" class="collision"/>
          <body name="link3" pos="0 -0.316 0" quat="1 1 0 0">
            <joint name="robot0_joint3"/>
            <inertial mass="3.228604" pos="2.7518e-2 3.9252e-2 -6.6502e-2"
              fullinertia="3.7242e-2 3.6155e-2 1.083e-2 -4.761e-3 -1.1396e-2 -1.2805e-2"/>
            <geom mesh="link3_0" material="white" class="visual"/>
            <geom mesh="link3_1" material="white" class="visual"/>
            <geom mesh="link3_2" material="white" class="visual"/>
            <geom mesh="link3_3" material="black" class="visual"/>
            <geom mesh="link3_c" class="collision"/>
            <body name="link4" pos="0.0825 0 0" quat="1 1 0 0">
              <inertial mass="3.587895" pos="-5.317e-2 1.04419e-1 2.7454e-2"
                fullinertia="2.5853e-2 1.9552e-2 2.8323e-2 7.796e-3 -1.332e-3 8.641e-3"/>
              <joint name="robot0_joint4" range="-3.0718 -0.0698"/>
              <geom mesh="link4_0" material="white" class="visual"/>
              <geom mesh="link4_1" material="white" class="visual"/>
              <geom mesh="link4_2" material="black" class="visual"/>
              <geom mesh="link4_3" material="white" class="visual"/>
              <geom mesh="link4_c" class="collision"/>
              <body name="link5" pos="-0.0825 0.384 0" quat="1 -1 0 0">
                <inertial mass="1.225946" pos="-1.1953e-2 4.1065e-2 -3.8437e-2"
                  fullinertia="3.5549e-2 2.9474e-2 8.627e-3 -2.117e-3 -4.037e-3 2.29e-4"/>
                <joint name="robot0_joint5"/>
                <geom mesh="link5_0" material="black" class="visual"/>
                <geom mesh="link5_1" material="white" class="visual"/>
                <geom mesh="link5_2" material="white" class="visual"/>
                <geom mesh="link5_c0" class="collision"/>
                <geom mesh="link5_c1" class="collision"/>
                <geom mesh="link5_c2" class="collision"/>
                <body name="link6" quat="1 1 0 0">
                  <inertial mass="1.666555" pos="6.0149e-2 -1.4117e-2 -1.0517e-2"
                    fullinertia="1.964e-3 4.354e-3 5.433e-3 1.09e-4 -1.158e-3 3.41e-4"/>
                  <joint name="robot0_joint6" range="-0.0175 3.7525"/>
                  <geom mesh="link6_0" material="off_white" class="visual"/>
                  <geom mesh="link6_1" material="white" class="visual"/>
                  <geom mesh="link6_2" material="black" class="visual"/>
                  <geom mesh="link6_3" material="white" class="visual"/>
                  <geom mesh="link6_4" material="white" class="visual"/>
                  <geom mesh="link6_5" material="white" class="visual"/>
                  <geom mesh="link6_6" material="white" class="visual"/>
                  <geom mesh="link6_7" material="light_blue" class="visual"/>
                  <geom mesh="link6_8" material="light_blue" class="visual"/>
                  <geom mesh="link6_9" material="black" class="visual"/>
                  <geom mesh="link6_10" material="black" class="visual"/>
                  <geom mesh="link6_11" material="white" class="visual"/>
                  <geom mesh="link6_12" material="green" class="visual"/>
                  <geom mesh="link6_13" material="white" class="visual"/>
                  <geom mesh="link6_14" material="black" class="visual"/>
                  <geom mesh="link6_15" material="black" class="visual"/>
                  <geom mesh="link6_16" material="white" class="visual"/>
                  <geom mesh="link6_c" class="collision"/>
                  <body name="link7" pos="0.088 0 0" quat="1 1 0 0">
                    <inertial mass="7.35522e-01" pos="1.0517e-2 -4.252e-3 6.1597e-2"
                      fullinertia="1.2516e-2 1.0027e-2 4.815e-3 -4.28e-4 -1.196e-3 -7.41e-4"/>
                    <joint name="robot0_joint7"/>
                    <geom mesh="link7_0" material="white" class="visual"/>
                    <geom mesh="link7_1" material="black" class="visual"/>
                    <geom mesh="link7_2" material="black" class="visual"/>
                    <geom mesh="link7_3" material="black" class="visual"/>
                    <geom mesh="link7_4" material="black" class="visual"/>
                    <geom mesh="link7_5" material="black" class="visual"/>
                    <geom mesh="link7_6" material="black" class="visual"/>
                    <geom mesh="link7_7" material="white" class="visual"/>
                    <geom mesh="link7_c" class="collision"/>
                    <!-- Using right_hand to match original -->
                    <body name="right_hand" pos="0 0 0.1065" quat="0.924 0 0 -0.383">
                      <inertial mass="0.73" pos="-0.01 0 0.03" diaginertia="0.001 0.0025 0.0017"/>
                      <geom mesh="hand_0" material="off_white" class="visual"/>
                      <geom mesh="hand_1" material="black" class="visual"/>
                      <geom mesh="hand_2" material="black" class="visual"/>
                      <geom mesh="hand_3" material="white" class="visual"/>
                      <geom mesh="hand_4" material="off_white" class="visual"/>
                      <geom mesh="hand_c" class="collision"/>
                      
                      <!-- Added essential camera and site elements from original model -->
                      <camera mode="fixed" name="eye_in_hand" pos="0.05 0 0" quat="0 0.707108 0.707108 0" fovy="75"/>
                      <site name="grip_site" pos="0 0 0" size="0.01 0.01 0.01" rgba="1 0 0 0.5" type="sphere" group="1"/>
                      <site name="ee_x" pos="0.1 0 0" size="0.005 .1" quat="0.707105 0 0.707108 0" rgba="1 0 0 0" type="cylinder" group="1"/>
                      <site name="ee_y" pos="0 0.1 0" size="0.005 .1" quat="0.707105 0.707108 0 0" rgba="0 1 0 0" type="cylinder" group="1"/>
                      <site name="ee_z" pos="0 0 0.1" size="0.005 .1" quat="1 0 0 0" rgba="0 0 1 0" type="cylinder" group="1"/>
                      
                      <body name="gripper0_right_leftfinger" pos="0 0 0.0584">
                        <inertial mass="0.015" pos="0 0 0" diaginertia="2.375e-6 2.375e-6 7.5e-7"/>
                        <joint name="gripper0_right_finger_joint1" class="finger"/>
                        <geom mesh="finger_0" material="off_white" class="visual"/>
                        <geom mesh="finger_1" material="black" class="visual"/>
                        <geom mesh="finger_0" class="collision"/>
                        <geom name="left_sensor_pad" type="box" size="0.005 0.001 0.015" pos="0 0.006 0.025" rgba="0.3 0.3 0.8 0.5" material="sensor_pad_material" group="2"/>
                        
                        <!-- Add all left taxel sites here -->
                        <site name="left_taxel_0_0" pos="-0.005000 0.006 0.010000" size="0.001" rgba="0 0 1 0.5" type="sphere" />
                        <site name="left_taxel_0_1" pos="-0.001667 0.006 0.010000" size="0.001" rgba="0 0 1 0.5" type="sphere" />
                        <site name="left_taxel_0_2" pos="0.001667 0.006 0.010000" size="0.001" rgba="0 0 1 0.5" type="sphere" />
                        <site name="left_taxel_0_3" pos="0.005000 0.006 0.010000" size="0.001" rgba="0 0 1 0.5" type="sphere" />
                        <site name="left_taxel_1_0" pos="-0.005000 0.006 0.025000" size="0.001" rgba="0 0 1 0.5" type="sphere" />
                        <site name="left_taxel_1_1" pos="-0.001667 0.006 0.025000" size="0.001" rgba="0 0 1 0.5" type="sphere" />
                        <site name="left_taxel_1_2" pos="0.001667 0.006 0.025000" size="0.001" rgba="0 0 1 0.5" type="sphere" />
                        <site name="left_taxel_1_3" pos="0.005000 0.006 0.025000" size="0.001" rgba="0 0 1 0.5" type="sphere" />
                        <site name="left_taxel_2_0" pos="-0.005000 0.006 0.040000" size="0.001" rgba="0 0 1 0.5" type="sphere" />
                        <site name="left_taxel_2_1" pos="-0.001667 0.006 0.040000" size="0.001" rgba="0 0 1 0.5" type="sphere" />
                        <site name="left_taxel_2_2" pos="0.001667 0.006 0.040000" size="0.001" rgba="0 0 1 0.5" type="sphere" />
                        <site name="left_taxel_2_3" pos="0.005000 0.006 0.040000" size="0.001" rgba="0 0 1 0.5" type="sphere" />
                      </body>
                      <body name="gripper0_right_rightfinger" pos="0 0 0.0584" quat="0 0 0 1">
                        <inertial mass="0.015" pos="0 0 0" diaginertia="2.375e-6 2.375e-6 7.5e-7"/>
                        <joint name="gripper0_right_finger_joint2" class="finger"/>
                        <geom mesh="finger_0" material="off_white" class="visual"/>
                        <geom mesh="finger_1" material="black" class="visual"/>
                        <geom mesh="finger_0" class="collision"/>
                        <geom name="right_sensor_pad" type="box" size="0.005 0.001 0.015" pos="0 -0.006 0.025" rgba="0.3 0.3 0.8 0.5" material="sensor_pad_material" group="2"/>
                        
                        <!-- Add all right taxel sites here -->
                        <site name="right_taxel_0_0" pos="-0.005000 -0.006 0.010000" size="0.001" rgba="1 0 0 0.5" type="sphere" />
                        <site name="right_taxel_0_1" pos="-0.001667 -0.006 0.010000" size="0.001" rgba="1 0 0 0.5" type="sphere" />
                        <site name="right_taxel_0_2" pos="0.001667 -0.006 0.010000" size="0.001" rgba="1 0 0 0.5" type="sphere" />
                        <site name="right_taxel_0_3" pos="0.005000 -0.006 0.010000" size="0.001" rgba="1 0 0 0.5" type="sphere" />
                        <site name="right_taxel_1_0" pos="-0.005000 -0.006 0.025000" size="0.001" rgba="1 0 0 0.5" type="sphere" />
                        <site name="right_taxel_1_1" pos="-0.001667 -0.006 0.025000" size="0.001" rgba="1 0 0 0.5" type="sphere" />
                        <site name="right_taxel_1_2" pos="0.001667 -0.006 0.025000" size="0.001" rgba="1 0 0 0.5" type="sphere" />
                        <site name="right_taxel_1_3" pos="0.005000 -0.006 0.025000" size="0.001" rgba="1 0 0 0.5" type="sphere" />
                        <site name="right_taxel_2_0" pos="-0.005000 -0.006 0.040000" size="0.001" rgba="1 0 0 0.5" type="sphere" />
                        <site name="right_taxel_2_1" pos="-0.001667 -0.006 0.040000" size="0.001" rgba="1 0 0 0.5" type="sphere" />
                        <site name="right_taxel_2_2" pos="0.001667 -0.006 0.040000" size="0.001" rgba="1 0 0 0.5" type="sphere" />
                        <site name="right_taxel_2_3" pos="0.005000 -0.006 0.040000" size="0.001" rgba="1 0 0 0.5" type="sphere" />
                      </body>
                    </body>
                  </body>
                </body>
              </body>
            </body>
          </body>
        </body>
      </body>
    </body>

    <camera mode="fixed" name="frontview" pos="1.6 0.0 1.45" quat="0.56 0.43 0.43 0.56" />
    <camera mode="fixed" name="birdview" pos="-0.2 0.0 3.0" quat="0.7071 0 0 0.7071" />
    <camera mode="fixed" name="agentview" pos="0.5 0.0 1.35" quat="0.653 0.271 0.271 0.653" />
    <camera mode="fixed" name="sideview" pos="-0.05651774593317116 1.2761224129427358 1.4879572214102434" quat="0.009905065491771751 0.006877963156909582 0.5912228352893879 0.806418094001364" />

    <!-- Simple boundary walls (simplified from the base model) -->
    <geom pos="0 0 0.05" size="0.8 0.8 0.01" type="plane" conaffinity="1" contype="1" group="3" name="boundary"/>
  </worldbody>

  <tendon>
    <fixed name="split">
      <joint joint="gripper0_right_finger_joint1" coef="0.5"/>
      <joint joint="gripper0_right_finger_joint2" coef="0.5"/>
    </fixed>
  </tendon>

  <equality>
    <joint joint1="gripper0_right_finger_joint1" joint2="gripper0_right_finger_joint2" solimp="0.95 0.99 0.001" solref="0.005 1"/>
  </equality>

  <!-- IMPORTANT CHANGE: Renamed actuators to match original -->
  <actuator>
    <motor ctrllimited="true" ctrlrange="-80.0 80.0" joint="robot0_joint1" name="robot0_torq_j1"/>
    <motor ctrllimited="true" ctrlrange="-80.0 80.0" joint="robot0_joint2" name="robot0_torq_j2"/>
    <motor ctrllimited="true" ctrlrange="-80.0 80.0" joint="robot0_joint3" name="robot0_torq_j3"/>
    <motor ctrllimited="true" ctrlrange="-80.0 80.0" joint="robot0_joint4" name="robot0_torq_j4"/>
    <motor ctrllimited="true" ctrlrange="-80.0 80.0" joint="robot0_joint5" name="robot0_torq_j5"/>
    <motor ctrllimited="true" ctrlrange="-12.0 12.0" joint="robot0_joint6" name="robot0_torq_j6"/>
    <motor ctrllimited="true" ctrlrange="-12.0 12.0" joint="robot0_joint7" name="robot0_torq_j7"/>
    <position ctrllimited="true" ctrlrange="0.0 0.04" joint="gripper0_right_finger_joint1" kp="1000" name="gripper0_right_gripper_finger_joint1" forcelimited="true" forcerange="-20 20"/>
    <position ctrllimited="true" ctrlrange="-0.04 0.0" joint="gripper0_right_finger_joint2" kp="1000" name="gripper0_right_gripper_finger_joint2" forcelimited="true" forcerange="-20 20"/>
  </actuator>

  <sensor>
    <!-- Added essential force sensors from original -->
    <force name="gripper0_right_force_ee" site="grip_site" />
    <torque name="gripper0_right_torque_ee" site="grip_site" />
    
    <!-- Touch sensors for tactile sensing -->
    <touch name="left_taxel_0_0_sensor" site="left_taxel_0_0" />
    <touch name="right_taxel_0_0_sensor" site="right_taxel_0_0" />
    <touch name="left_taxel_0_1_sensor" site="left_taxel_0_1" />
    <touch name="right_taxel_0_1_sensor" site="right_taxel_0_1" />
    <touch name="left_taxel_0_2_sensor" site="left_taxel_0_2" />
    <touch name="right_taxel_0_2_sensor" site="right_taxel_0_2" />
    <touch name="left_taxel_0_3_sensor" site="left_taxel_0_3" />
    <touch name="right_taxel_0_3_sensor" site="right_taxel_0_3" />
    <touch name="left_taxel_1_0_sensor" site="left_taxel_1_0" />
    <touch name="right_taxel_1_0_sensor" site="right_taxel_1_0" />
    <touch name="left_taxel_1_1_sensor" site="left_taxel_1_1" />
    <touch name="right_taxel_1_1_sensor" site="right_taxel_1_1" />
    <touch name="left_taxel_1_2_sensor" site="left_taxel_1_2" />
    <touch name="right_taxel_1_2_sensor" site="right_taxel_1_2" />
    <touch name="left_taxel_1_3_sensor" site="left_taxel_1_3" />
    <touch name="right_taxel_1_3_sensor" site="right_taxel_1_3" />
    <touch name="left_taxel_2_0_sensor" site="left_taxel_2_0" />
    <touch name="right_taxel_2_0_sensor" site="right_taxel_2_0" />
    <touch name="left_taxel_2_1_sensor" site="left_taxel_2_1" />
    <touch name="right_taxel_2_1_sensor" site="right_taxel_2_1" />
    <touch name="left_taxel_2_2_sensor" site="left_taxel_2_2" />
    <touch name="right_taxel_2_2_sensor" site="right_taxel_2_2" />
    <touch name="left_taxel_2_3_sensor" site="left_taxel_2_3" />
    <touch name="right_taxel_2_3_sensor" site="right_taxel_2_3" />
  </sensor>
</mujoco>